C:\Users\leon\PycharmProjects\Course01\venv\Scripts\python.exe C:/Users/leon/PycharmProjects/Course01/PROJECTS/Project01-RestAPI/backend_testing.py
Traceback (most recent call last):
  File "C:\Users\leon\PycharmProjects\Course01\venv\lib\site-packages\urllib3\connectionpool.py", line 703, in urlopen
    httplib_response = self._make_request(
  File "C:\Users\leon\PycharmProjects\Course01\venv\lib\site-packages\urllib3\connectionpool.py", line 449, in _make_request
    six.raise_from(e, None)
  File "<string>", line 3, in raise_from
  File "C:\Users\leon\PycharmProjects\Course01\venv\lib\site-packages\urllib3\connectionpool.py", line 444, in _make_request
    httplib_response = conn.getresponse()
  File "C:\Users\leon\AppData\Local\Programs\Python\Python38-32\lib\http\client.py", line 1322, in getresponse
    response.begin()
  File "C:\Users\leon\AppData\Local\Programs\Python\Python38-32\lib\http\client.py", line 303, in begin
    version, status, reason = self._read_status()
  File "C:\Users\leon\AppData\Local\Programs\Python\Python38-32\lib\http\client.py", line 264, in _read_status
    line = str(self.fp.readline(_MAXLINE + 1), "iso-8859-1")
  File "C:\Users\leon\AppData\Local\Programs\Python\Python38-32\lib\socket.py", line 669, in readinto
    return self._sock.recv_into(b)
ConnectionResetError: [WinError 10054] An existing connection was forcibly closed by the remote host

During handling of the above exception, another exception occurred:

Traceback (most recent call last):
  File "C:\Users\leon\PycharmProjects\Course01\venv\lib\site-packages\requests\adapters.py", line 489, in send
    resp = conn.urlopen(
  File "C:\Users\leon\PycharmProjects\Course01\venv\lib\site-packages\urllib3\connectionpool.py", line 785, in urlopen
    retries = retries.increment(
  File "C:\Users\leon\PycharmProjects\Course01\venv\lib\site-packages\urllib3\util\retry.py", line 550, in increment
    raise six.reraise(type(error), error, _stacktrace)
  File "C:\Users\leon\PycharmProjects\Course01\venv\lib\site-packages\urllib3\packages\six.py", line 769, in reraise
    raise value.with_traceback(tb)
  File "C:\Users\leon\PycharmProjects\Course01\venv\lib\site-packages\urllib3\connectionpool.py", line 703, in urlopen
    httplib_response = self._make_request(
  File "C:\Users\leon\PycharmProjects\Course01\venv\lib\site-packages\urllib3\connectionpool.py", line 449, in _make_request
    six.raise_from(e, None)
  File "<string>", line 3, in raise_from
  File "C:\Users\leon\PycharmProjects\Course01\venv\lib\site-packages\urllib3\connectionpool.py", line 444, in _make_request
    httplib_response = conn.getresponse()
  File "C:\Users\leon\AppData\Local\Programs\Python\Python38-32\lib\http\client.py", line 1322, in getresponse
    response.begin()
  File "C:\Users\leon\AppData\Local\Programs\Python\Python38-32\lib\http\client.py", line 303, in begin
    version, status, reason = self._read_status()
  File "C:\Users\leon\AppData\Local\Programs\Python\Python38-32\lib\http\client.py", line 264, in _read_status
    line = str(self.fp.readline(_MAXLINE + 1), "iso-8859-1")
  File "C:\Users\leon\AppData\Local\Programs\Python\Python38-32\lib\socket.py", line 669, in readinto
    return self._sock.recv_into(b)
urllib3.exceptions.ProtocolError: ('Connection aborted.', ConnectionResetError(10054, 'An existing connection was forcibly closed by the remote host', None, 10054, None))

During handling of the above exception, another exception occurred:

Traceback (most recent call last):
  File "C:/Users/leon/PycharmProjects/Course01/PROJECTS/Project01-RestAPI/backend_testing.py", line 12, in <module>
    res_post = requests.post(f'http://127.0.0.1:5000/users/{user_id}', json={"user_name": f'{user_name}'})
  File "C:\Users\leon\PycharmProjects\Course01\venv\lib\site-packages\requests\api.py", line 115, in post
    return request("post", url, data=data, json=json, **kwargs)
  File "C:\Users\leon\PycharmProjects\Course01\venv\lib\site-packages\requests\api.py", line 59, in request
    return session.request(method=method, url=url, **kwargs)
  File "C:\Users\leon\PycharmProjects\Course01\venv\lib\site-packages\requests\sessions.py", line 587, in request
    resp = self.send(prep, **send_kwargs)
  File "C:\Users\leon\PycharmProjects\Course01\venv\lib\site-packages\requests\sessions.py", line 701, in send
    r = adapter.send(request, **kwargs)
  File "C:\Users\leon\PycharmProjects\Course01\venv\lib\site-packages\requests\adapters.py", line 547, in send
    raise ConnectionError(err, request=request)
requests.exceptions.ConnectionError: ('Connection aborted.', ConnectionResetError(10054, 'An existing connection was forcibly closed by the remote host', None, 10054, None))

Process finished with exit code 1
